Workbook

Sheet Eneryg flow sharing
B2: Marked in yellow are those that are direct links to the sheets and not hard-coded values /Rud | I2: =Energy_KPI_export!I2 -> 599.12546
B4: Natural Gas CHP | G4: Biogas Plant | N4: Natural Gas CHP
B5: Utility type | C5: Input - TJ/y | D5: Output - TJ/y | H5: Input Electricity | I5: Input Heat | N5: Utility type | O5: Input - TJ/y | P5: Output - TJ/y
B6: Low pressure steam | C6: ='Natural Gas CHP'!C102 -> 0 | D6: =abs('Natural Gas CHP'!E102) -> 611.13758 | G6: kWh/y | H6: 4143.8836 | I6: 14981.733 | N6: Low pressure steam | O6: 0 | P6: 696.86051
B7: Mid pressure steam | C7: ='Natural Gas CHP'!C103 -> 0 | D7: =abs('Natural Gas CHP'!E103) -> 511.76342 | N7: Mid pressure steam | O7: 0 | P7: 583.54735
B8: High pressure steam | C8: ='Natural Gas CHP'!C104 -> 0 | D8: =abs('Natural Gas CHP'!E104) -> 444.06984 | N8: High pressure steam | O8: 0 | P8: 506.35855
B9: Cooling water | C9: ='Natural Gas CHP'!C105 -> 940.53459 | D9: =abs('Natural Gas CHP'!E105) -> 0 | N9: Cooling water | O9: 1072.4613 | P9: 0
B10: Fired Heat | C10: ='Natural Gas CHP'!C106 -> 599.12546 | D10: =abs('Natural Gas CHP'!E106) -> 0 | N10: Fired Heat | O10: 683.16348 | P10: 0
B11: Electricity - kWh/y | C11: ='Natural Gas CHP'!D109 -> 3.6239569e+08 | D11: =abs('Natural Gas CHP'!F109) -> 735819522 | N11: Electricity - kWh/y | O11: 4.1322814e+08 | P11: 8.3903132e+08
B14: Olefins Production Plant | G14: Methanol Production Plant
B15: Utility type | C15: Input - TJ/y | D15: Output - TJ/y | G15: Utility type | H15: Input - TJ/y | I15: Output - TJ/y
B16: Low pressure steam | C16: ='Olefins Production Plant'!C125 -> 11814.987 | D16: ='Olefins Production Plant'!E125 -> -4038.184 | G16: Low pressure steam | H16: 377.10549 | I16: 183.95329
B17: Mid pressure steam | C17: ='Olefins Production Plant'!C126 -> 9900.5797 | D17: ='Olefins Production Plant'!E126 -> -15225.437 | G17: Mid pressure steam | H17: 211.18307 | I17: 670.83929
B18: High pressure steam | C18: ='Olefins Production Plant'!C127 -> 0 | D18: ='Olefins Production Plant'!E127 -> -9069.094 | G18: High pressure steam | H18: 0 | I18: 708.81075
B19: Cooling water | C19: ='Olefins Production Plant'!C128 -> 20303.523 | D19: ='Olefins Production Plant'!E128 -> 0 | G19: Cooling water | H19: 4134.383 | I19: 0
B20: Very High pressure steam | C20: ='Olefins Production Plant'!C130 -> 0 | D20: ='Olefins Production Plant'!E130 -> -2979.3755 | G20: Electricity - kWh/y | H20: 1.9199038e+08 | I20: 0
B21: Electricity - kWh/y | C21: ='Olefins Production Plant'!D134 -> 2.6386888e+08 | D21: =abs('Olefins Production Plant'!F134) -> 56745852
B24: Aromatics Production Plant | G24: DME Plant
B25: Utility type | C25: Input - TJ/y | D25: Output - TJ/y | G25: Utility type | H25: Input - TJ/y | I25: Output - TJ/y
B26: Very low pressure steam | C26: 1982.3174 | D26: 1923.4683 | G26: Very low pressure steam | H26: 0 | I26: 52.06363
B27: Low pressure steam | C27: 1462.2693 | D27: 428.76889 | G27: Low pressure steam | H27: 0 | I27: 63.969345
B28: Mid pressure steam | C28: 3899.124 | D28: 0 | G28: Mid pressure steam | H28: 445.08236 | I28: 0
B29: High pressure steam | C29: 1489.0847 | D29: 0 | G29: High pressure steam | H29: 0 | I29: 0
B30: Cooling water | C30: 6917.1944 | D30: 0 | G30: Cooling water | H30: 659.34272 | I30: 0
B31: Chilled water | C31: 87.775641 | D31: 0 | G31: Electricity - kWh/y | H31: 19426831 | I31: 0
B32: Electricity - kWh/y | C32: 42665373 | D32: 0
B37: Utility type broad category | C37: Specific company-utility output | D37: Utility type | E37: Giver | F37: Receiver | G37: Net | H37: Surplus or deficit? | I37: Remainder if surplus | J37: Notes | K37: Amount being sent
B38: SELF-SHARING | C38: Self-sharing | D38: Electricity | E38: CHP | F38: CHP | G38: =C11-#REF! -> #REF! | H38: =if(G38 < 0,"Surplus","Deficit") -> #REF! | I38: =IF(G38<0,-G38,0) -> #REF! | K38: =C11 -> 3.6239569e+08
D39: Low pressure steam | E39: Olefins | F39: Olefins | G39: =C16-#REF! -> #REF! | H39: =if(G39 < 0,"Surplus","Deficit") -> #REF! | I39: =IF(G39<0,-G39,0) -> #REF! | K39: =#REF! -> #REF!
D40: Medium pressure steam | E40: Olefins | F40: Olefins | G40: =C17-#REF! -> #REF! | H40: =if(G40 < 0,"Surplus","Deficit") -> #REF! | I40: =IF(G40<0,-G40,0) -> #REF! | K40: =C17 -> 9900.5797
D41: Electricity | E41: Olefins | F41: Olefins | G41: =C20-D21 -> -56745852 | H41: =if(G41 < 0,"Surplus","Deficit") -> Surplus | I41: =IF(G41<0,-G41,0) -> 56745852 | K41: =D21 -> 56745852
D42: Very low pressure steam | E42: Aromatics | F42: Aromatics | G42: =C26-D26 -> 58.849144 | H42: =if(G42 < 0,"Surplus","Deficit") -> Deficit | I42: =IF(G42<0,-G42,0) -> 0 | K42: =D26 -> 1923.4683
D43: Low pressure steam | E43: Aromatics | F43: Aromatics | G43: =C27-D27 -> 1033.5004 | H43: =if(G43 < 0,"Surplus","Deficit") -> Deficit | I43: =IF(G43<0,-G43,0) -> 0 | K43: =D27 -> 428.76889
D44: Low pressure steam | E44: Methanol | F44: Methanol | G44: =H16-I16 -> 193.1522 | H44: =if(G44 < 0,"Surplus","Deficit") -> Deficit | I44: =IF(G44<0,-G44,0) -> 0 | K44: =I16 -> 183.95329
D45: Medium pressure steam | E45: Methanol | F45: Methanol | G45: =H17-I17 -> -459.65622 | H45: =if(G45 < 0,"Surplus","Deficit") -> Surplus | I45: =IF(G45<0,-G45,0) -> 459.65622 | K45: =H17 -> 211.18307
B46: VERY LOW PRESSURE STEAM | C46: DME VLPS output | D46: Very low pressure steam | E46: DME | F46: Aromatics | G46: =G42-I26 -> 6.7855142 | H46: =if(G46 < 0,"Surplus","Deficit") -> Deficit | I46: =IF(G46<0,-G46,0) -> 0 | K46: =I26 -> 52.06363
B47: LOW PRESSURE STEAM | C47: CHP LPS output | D47: Low pressure steam | E47: CHP | F47: Olefins | G47: =G39-#REF! -> #REF! | H47: =if(G47 < 0,"Surplus","Deficit") -> #REF! | I47: =IF(G47<0,-G47,0) -> #REF! | J47: First to methanol, then to aromatics, then final surplus to olefins | K47: =I49-K48 -> #REF!
D48: Low pressure steam | E48: CHP | F48: Aromatics | G48: =G43-#REF! -> #REF! | H48: =if(G48 < 0,"Surplus","Deficit") -> #REF! | I48: =IF(G48<0,-G48,0) -> #REF! | K48: =G48 -> #REF!
D49: Low pressure steam | E49: CHP | F49: Methanol | G49: =G44-#REF! -> #REF! | H49: =if(G49 < 0,"Surplus","Deficit") -> #REF! | I49: =IF(G49<0,-G49,0) -> #REF! | K49: =G44 -> 193.1522
C50: Olefins LPS output | D50: Low pressure steam | E50: Olefins | F50: Aromatics | G50: =C27-I39 -> #REF! | H50: =if(G50 < 0,"Surplus","Deficit") -> #REF! | I50: =IF(G50<0,-G50,0) -> #REF! | J50: After olefins self-sharing none is left, so ignore all
...

Sheet Energy_KPI_cooling_water_export
A1: Company | B1: input_cooling_water_kt_y | C1: output_cooling_water_kt_y
A2: Aromatics plant | B2: ='Aromatics Production Plant'!D147 -> 110518.64 | C2: ='Aromatics Production Plant'!F147 -> 0
A3: Biogas plant | B3: 0 | C3: 0
A4: CHP plant | B4: ='Natural Gas CHP'!D105 -> 15027.296 | C4: ='Natural Gas CHP'!F105 -> 0
A5: DME plant | B5: ='DME Plant'!D101 -> 10508.277 | C5: ='DME Plant'!F101 -> 0
A6: Methanol plant | B6: ='Methanol Production Plant'!D108 -> 65891.824 | C6: ='Methanol Production Plant'!F108 -> 0
A7: Olefins plant | B7: ='Olefins Production Plant'!D128 -> 323673.76 | C7: ='Olefins Production Plant'!F128 -> 0

Sheet Energy_KPI_export
A1: Company | B1: Very low pressure steam | C1: Low pressure steam | D1: Mid pressure steam | E1: High pressure steam | F1: Very High pressure steam | G1: Cooling water | H1: Chilled water | I1: Fired Heat | J1: Electricity - kWh/y | K1: Input_Output
A2: CHP plant | B2: {=iferror(index('Eneryg flow sharing'!$C$6:$D$11,match(B$1,'Eneryg flow sharing'!$B$6:$B$11,0),1+($K2="Output")),"")} | C2: {=iferror(index('Eneryg flow sharing'!$C$6:$D$11,match(C$1,'Eneryg flow sharing'!$B$6:$B$11,0),1+($K2="Output")),"")} -> 0 | D2: {=iferror(index('Eneryg flow sharing'!$C$6:$D$11,match(D$1,'Eneryg flow sharing'!$B$6:$B$11,0),1+($K2="Output")),"")} -> 0 | E2: {=iferror(index('Eneryg flow sharing'!$C$6:$D$11,match(E$1,'Eneryg flow sharing'!$B$6:$B$11,0),1+($K2="Output")),"")} -> 0 | F2: {=iferror(index('Eneryg flow sharing'!$C$6:$D$11,match(F$1,'Eneryg flow sharing'!$B$6:$B$11,0),1+($K2="Output")),"")} | G2: {=iferror(index('Eneryg flow sharing'!$C$6:$D$11,match(G$1,'Eneryg flow sharing'!$B$6:$B$11,0),1+($K2="Output")),"")} -> 940.53459 | H2: {=iferror(index('Eneryg flow sharing'!$C$6:$D$11,match(H$1,'Eneryg flow sharing'!$B$6:$B$11,0),1+($K2="Output")),"")} | I2: {=iferror(index('Eneryg flow sharing'!$C$6:$D$11,match(I$1,'Eneryg flow sharing'!$B$6:$B$11,0),1+($K2="Output")),"")} -> 599.12546 | J2: {=iferror(index('Eneryg flow sharing'!$C$6:$D$11,match(J$1,'Eneryg flow sharing'!$B$6:$B$11,0),1+($K2="Output")),"")} -> 3.6239569e+08 | K2: Input
A3: Olefins plant | B3: {=iferror(index('Eneryg flow sharing'!$C$16:$D$21,match(B$1,'Eneryg flow sharing'!$B$16:$B$21,0),1+($K3="Output")),"")} | C3: {=iferror(index('Eneryg flow sharing'!$C$16:$D$21,match(C$1,'Eneryg flow sharing'!$B$16:$B$21,0),1+($K3="Output")),"")} -> 11814.987 | D3: {=iferror(index('Eneryg flow sharing'!$C$16:$D$21,match(D$1,'Eneryg flow sharing'!$B$16:$B$21,0),1+($K3="Output")),"")} -> 9900.5797 | E3: {=iferror(index('Eneryg flow sharing'!$C$16:$D$21,match(E$1,'Eneryg flow sharing'!$B$16:$B$21,0),1+($K3="Output")),"")} -> 0 | F3: {=iferror(index('Eneryg flow sharing'!$C$16:$D$21,match(F$1,'Eneryg flow sharing'!$B$16:$B$21,0),1+($K3="Output")),"")} -> 0 | G3: {=iferror(index('Eneryg flow sharing'!$C$16:$D$21,match(G$1,'Eneryg flow sharing'!$B$16:$B$21,0),1+($K3="Output")),"")} -> 20303.523 | H3: {=iferror(index('Eneryg flow sharing'!$C$16:$D$21,match(H$1,'Eneryg flow sharing'!$B$16:$B$21,0),1+($K3="Output")),"")} | I3: {=iferror(index('Eneryg flow sharing'!$C$16:$D$21,match(I$1,'Eneryg flow sharing'!$B$16:$B$21,0),1+($K3="Output")),"")} | J3: {=iferror(index('Eneryg flow sharing'!$C$16:$D$21,match(J$1,'Eneryg flow sharing'!$B$16:$B$21,0),1+($K3="Output")),"")} -> 2.6386888e+08 | K3: Input
A4: Aromatics plant | B4: {=iferror(index('Eneryg flow sharing'!$C$26:$D$32,match(B$1,'Eneryg flow sharing'!$B$26:$B$32,0),1+($K4="Output")),"")} -> 1982.3174 | C4: {=iferror(index('Eneryg flow sharing'!$C$26:$D$32,match(C$1,'Eneryg flow sharing'!$B$26:$B$32,0),1+($K4="Output")),"")} -> 1462.2693 | D4: {=iferror(index('Eneryg flow sharing'!$C$26:$D$32,match(D$1,'Eneryg flow sharing'!$B$26:$B$32,0),1+($K4="Output")),"")} -> 3899.124 | E4: {=iferror(index('Eneryg flow sharing'!$C$26:$D$32,match(E$1,'Eneryg flow sharing'!$B$26:$B$32,0),1+($K4="Output")),"")} -> 1489.0847 | F4: {=iferror(index('Eneryg flow sharing'!$C$26:$D$32,match(F$1,'Eneryg flow sharing'!$B$26:$B$32,0),1+($K4="Output")),"")} | G4: {=iferror(index('Eneryg flow sharing'!$C$26:$D$32,match(G$1,'Eneryg flow sharing'!$B$26:$B$32,0),1+($K4="Output")),"")} -> 6917.1944 | H4: {=iferror(index('Eneryg flow sharing'!$C$26:$D$32,match(H$1,'Eneryg flow sharing'!$B$26:$B$32,0),1+($K4="Output")),"")} -> 87.775641 | I4: {=iferror(index('Eneryg flow sharing'!$C$26:$D$32,match(I$1,'Eneryg flow sharing'!$B$26:$B$32,0),1+($K4="Output")),"")} | J4: {=iferror(index('Eneryg flow sharing'!$C$26:$D$32,match(J$1,'Eneryg flow sharing'!$B$26:$B$32,0),1+($K4="Output")),"")} -> 42665373 | K4: Input
A5: Biogas plant | I5: ='Eneryg flow sharing'!$I$6 -> 14981.733 | J5: ='Eneryg flow sharing'!$H$6 -> 4143.8836 | K5: Input
A6: Methanol plant | B6: {=iferror(index('Eneryg flow sharing'!$H$16:$I$21,match(B$1,'Eneryg flow sharing'!$G$16:$G$21,0),1+($K6="Output")),"")} | C6: {=iferror(index('Eneryg flow sharing'!$H$16:$I$21,match(C$1,'Eneryg flow sharing'!$G$16:$G$21,0),1+($K6="Output")),"")} -> 377.10549 | D6: {=iferror(index('Eneryg flow sharing'!$H$16:$I$21,match(D$1,'Eneryg flow sharing'!$G$16:$G$21,0),1+($K6="Output")),"")} -> 211.18307 | E6: {=iferror(index('Eneryg flow sharing'!$H$16:$I$21,match(E$1,'Eneryg flow sharing'!$G$16:$G$21,0),1+($K6="Output")),"")} -> 0 | F6: {=iferror(index('Eneryg flow sharing'!$H$16:$I$21,match(F$1,'Eneryg flow sharing'!$G$16:$G$21,0),1+($K6="Output")),"")} | G6: {=iferror(index('Eneryg flow sharing'!$H$16:$I$21,match(G$1,'Eneryg flow sharing'!$G$16:$G$21,0),1+($K6="Output")),"")} -> 4134.383 | H6: {=iferror(index('Eneryg flow sharing'!$H$16:$I$21,match(H$1,'Eneryg flow sharing'!$G$16:$G$21,0),1+($K6="Output")),"")} | I6: {=iferror(index('Eneryg flow sharing'!$H$16:$I$21,match(I$1,'Eneryg flow sharing'!$G$16:$G$21,0),1+($K6="Output")),"")} | J6: {=iferror(index('Eneryg flow sharing'!$H$16:$I$21,match(J$1,'Eneryg flow sharing'!$G$16:$G$21,0),1+($K6="Output")),"")} -> 1.9199038e+08 | K6: Input
A7: DME plant | B7: {=iferror(index('Eneryg flow sharing'!$H$26:$I$32,match(B$1,'Eneryg flow sharing'!$G$26:$G$32,0),1+($K7="Output")),"")} -> 0 | C7: {=iferror(index('Eneryg flow sharing'!$H$26:$I$32,match(C$1,'Eneryg flow sharing'!$G$26:$G$32,0),1+($K7="Output")),"")} -> 0 | D7: {=iferror(index('Eneryg flow sharing'!$H$26:$I$32,match(D$1,'Eneryg flow sharing'!$G$26:$G$32,0),1+($K7="Output")),"")} -> 445.08236 | E7: {=iferror(index('Eneryg flow sharing'!$H$26:$I$32,match(E$1,'Eneryg flow sharing'!$G$26:$G$32,0),1+($K7="Output")),"")} -> 0 | F7: {=iferror(index('Eneryg flow sharing'!$H$26:$I$32,match(F$1,'Eneryg flow sharing'!$G$26:$G$32,0),1+($K7="Output")),"")} | G7: {=iferror(index('Eneryg flow sharing'!$H$26:$I$32,match(G$1,'Eneryg flow sharing'!$G$26:$G$32,0),1+($K7="Output")),"")} -> 659.34272 | H7: {=iferror(index('Eneryg flow sharing'!$H$26:$I$32,match(H$1,'Eneryg flow sharing'!$G$26:$G$32,0),1+($K7="Output")),"")} | I7: {=iferror(index('Eneryg flow sharing'!$H$26:$I$32,match(I$1,'Eneryg flow sharing'!$G$26:$G$32,0),1+($K7="Output")),"")} | J7: {=iferror(index('Eneryg flow sharing'!$H$26:$I$32,match(J$1,'Eneryg flow sharing'!$G$26:$G$32,0),1+($K7="Output")),"")} -> 19426831 | K7: Input
A8: CHP plant | B8: {=iferror(index('Eneryg flow sharing'!$C$6:$D$11,match(B$1,'Eneryg flow sharing'!$B$6:$B$11,0),1+($K8="Output")),"")} | C8: {=iferror(index('Eneryg flow sharing'!$C$6:$D$11,match(C$1,'Eneryg flow sharing'!$B$6:$B$11,0),1+($K8="Output")),"")} -> 611.13758 | D8: {=iferror(index('Eneryg flow sharing'!$C$6:$D$11,match(D$1,'Eneryg flow sharing'!$B$6:$B$11,0),1+($K8="Output")),"")} -> 511.76342 | E8: {=iferror(index('Eneryg flow sharing'!$C$6:$D$11,match(E$1,'Eneryg flow sharing'!$B$6:$B$11,0),1+($K8="Output")),"")} -> 444.06984 | F8: {=iferror(index('Eneryg flow sharing'!$C$6:$D$11,match(F$1,'Eneryg flow sharing'!$B$6:$B$11,0),1+($K8="Output")),"")} | G8: {=iferror(index('Eneryg flow sharing'!$C$6:$D$11,match(G$1,'Eneryg flow sharing'!$B$6:$B$11,0),1+($K8="Output")),"")} -> 0 | H8: {=iferror(index('Eneryg flow sharing'!$C$6:$D$11,match(H$1,'Eneryg flow sharing'!$B$6:$B$11,0),1+($K8="Output")),"")} | I8: {=iferror(index('Eneryg flow sharing'!$C$6:$D$11,match(I$1,'Eneryg flow sharing'!$B$6:$B$11,0),1+($K8="Output")),"")} -> 0 | J8: {=iferror(index('Eneryg flow sharing'!$C$6:$D$11,match(J$1,'Eneryg flow sharing'!$B$6:$B$11,0),1+($K8="Output")),"")} -> 735819522 | K8: Output
A9: Olefins plant | B9: {=iferror(index('Eneryg flow sharing'!$C$16:$D$21,match(B$1,'Eneryg flow sharing'!$B$16:$B$21,0),1+($K9="Output")),"")} | C9: {=iferror(index('Eneryg flow sharing'!$C$16:$D$21,match(C$1,'Eneryg flow sharing'!$B$16:$B$21,0),1+($K9="Output")),"")} -> -4038.184 | D9: {=iferror(index('Eneryg flow sharing'!$C$16:$D$21,match(D$1,'Eneryg flow sharing'!$B$16:$B$21,0),1+($K9="Output")),"")} -> -15225.437 | E9: {=iferror(index('Eneryg flow sharing'!$C$16:$D$21,match(E$1,'Eneryg flow sharing'!$B$16:$B$21,0),1+($K9="Output")),"")} -> -9069.094 | F9: {=iferror(index('Eneryg flow sharing'!$C$16:$D$21,match(F$1,'Eneryg flow sharing'!$B$16:$B$21,0),1+($K9="Output")),"")} -> -2979.3755 | G9: {=iferror(index('Eneryg flow sharing'!$C$16:$D$21,match(G$1,'Eneryg flow sharing'!$B$16:$B$21,0),1+($K9="Output")),"")} -> 0 | H9: {=iferror(index('Eneryg flow sharing'!$C$16:$D$21,match(H$1,'Eneryg flow sharing'!$B$16:$B$21,0),1+($K9="Output")),"")} | I9: {=iferror(index('Eneryg flow sharing'!$C$16:$D$21,match(I$1,'Eneryg flow sharing'!$B$16:$B$21,0),1+($K9="Output")),"")} | J9: {=iferror(index('Eneryg flow sharing'!$C$16:$D$21,match(J$1,'Eneryg flow sharing'!$B$16:$B$21,0),1+($K9="Output")),"")} -> 56745852 | K9: Output
A10: Aromatics plant | B10: {=iferror(index('Eneryg flow sharing'!$C$26:$D$32,match(B$1,'Eneryg flow sharing'!$B$26:$B$32,0),1+($K10="Output")),"")} -> 1923.4683 | C10: {=iferror(index('Eneryg flow sharing'!$C$26:$D$32,match(C$1,'Eneryg flow sharing'!$B$26:$B$32,0),1+($K10="Output")),"")} -> 428.76889 | D10: {=iferror(index('Eneryg flow sharing'!$C$26:$D$32,match(D$1,'Eneryg flow sharing'!$B$26:$B$32,0),1+($K10="Output")),"")} -> 0 | E10: {=iferror(index('Eneryg flow sharing'!$C$26:$D$32,match(E$1,'Eneryg flow sharing'!$B$26:$B$32,0),1+($K10="Output")),"")} -> 0 | F10: {=iferror(index('Eneryg flow sharing'!$C$26:$D$32,match(F$1,'Eneryg flow sharing'!$B$26:$B$32,0),1+($K10="Output")),"")} | G10: {=iferror(index('Eneryg flow sharing'!$C$26:$D$32,match(G$1,'Eneryg flow sharing'!$B$26:$B$32,0),1+($K10="Output")),"")} -> 0 | H10: {=iferror(index('Eneryg flow sharing'!$C$26:$D$32,match(H$1,'Eneryg flow sharing'!$B$26:$B$32,0),1+($K10="Output")),"")} -> 0 | I10: {=iferror(index('Eneryg flow sharing'!$C$26:$D$32,match(I$1,'Eneryg flow sharing'!$B$26:$B$32,0),1+($K10="Output")),"")} | J10: {=iferror(index('Eneryg flow sharing'!$C$26:$D$32,match(J$1,'Eneryg flow sharing'!$B$26:$B$32,0),1+($K10="Output")),"")} -> 0 | K10: Output
A11: Biogas plant | K11: Output
A12: Methanol plant | B12: {=iferror(index('Eneryg flow sharing'!$H$16:$I$21,match(B$1,'Eneryg flow sharing'!$G$16:$G$21,0),1+($K12="Output")),"")} | C12: {=iferror(index('Eneryg flow sharing'!$H$16:$I$21,match(C$1,'Eneryg flow sharing'!$G$16:$G$21,0),1+($K12="Output")),"")} -> 183.95329 | D12: {=iferror(index('Eneryg flow sharing'!$H$16:$I$21,match(D$1,'Eneryg flow sharing'!$G$16:$G$21,0),1+($K12="Output")),"")} -> 670.83929 | E12: {=iferror(index('Eneryg flow sharing'!$H$16:$I$21,match(E$1,'Eneryg flow sharing'!$G$16:$G$21,0),1+($K12="Output")),"")} -> 708.81075 | F12: {=iferror(index('Eneryg flow sharing'!$H$16:$I$21,match(F$1,'Eneryg flow sharing'!$G$16:$G$21,0),1+($K12="Output")),"")} | G12: {=iferror(index('Eneryg flow sharing'!$H$16:$I$21,match(G$1,'Eneryg flow sharing'!$G$16:$G$21,0),1+($K12="Output")),"")} -> 0 | H12: {=iferror(index('Eneryg flow sharing'!$H$16:$I$21,match(H$1,'Eneryg flow sharing'!$G$16:$G$21,0),1+($K12="Output")),"")} | I12: {=iferror(index('Eneryg flow sharing'!$H$16:$I$21,match(I$1,'Eneryg flow sharing'!$G$16:$G$21,0),1+($K12="Output")),"")} | J12: {=iferror(index('Eneryg flow sharing'!$H$16:$I$21,match(J$1,'Eneryg flow sharing'!$G$16:$G$21,0),1+($K12="Output")),"")} -> 0 | K12: Output
A13: DME plant | B13: {=iferror(index('Eneryg flow sharing'!$H$26:$I$32,match(B$1,'Eneryg flow sharing'!$G$26:$G$32,0),1+($K13="Output")),"")} -> 52.06363 | C13: {=iferror(index('Eneryg flow sharing'!$H$26:$I$32,match(C$1,'Eneryg flow sharing'!$G$26:$G$32,0),1+($K13="Output")),"")} -> 63.969345 | D13: {=iferror(index('Eneryg flow sharing'!$H$26:$I$32,match(D$1,'Eneryg flow sharing'!$G$26:$G$32,0),1+($K13="Output")),"")} -> 0 | E13: {=iferror(index('Eneryg flow sharing'!$H$26:$I$32,match(E$1,'Eneryg flow sharing'!$G$26:$G$32,0),1+($K13="Output")),"")} -> 0 | F13: {=iferror(index('Eneryg flow sharing'!$H$26:$I$32,match(F$1,'Eneryg flow sharing'!$G$26:$G$32,0),1+($K13="Output")),"")} | G13: {=iferror(index('Eneryg flow sharing'!$H$26:$I$32,match(G$1,'Eneryg flow sharing'!$G$26:$G$32,0),1+($K13="Output")),"")} -> 0 | H13: {=iferror(index('Eneryg flow sharing'!$H$26:$I$32,match(H$1,'Eneryg flow sharing'!$G$26:$G$32,0),1+($K13="Output")),"")} | I13: {=iferror(index('Eneryg flow sharing'!$H$26:$I$32,match(I$1,'Eneryg flow sharing'!$G$26:$G$32,0),1+($K13="Output")),"")} | J13: {=iferror(index('Eneryg flow sharing'!$H$26:$I$32,match(J$1,'Eneryg flow sharing'!$G$26:$G$32,0),1+($K13="Output")),"")} -> 0 | K13: Output

Sheet Natural Gas CHP
B3: Natural gas CHP
B4: Process datasheet (Mass & Energy Balance)
B6: Production capacity | D6: 50 MW electricity and 120 ton/h of steam
B7: Operating hours per year | D7: 8000 h/y
B9: Overall Process Description
B10: This process description presents a cogeneration plant, also called combined heat and power plant (CHP), which uses natural gas to produce 50 MW electricity and 120 ton/h of steam. A cogeneration is a system that recaptures otherwise wasted thermal energy, usually from a heat engine (such as a steam turbine, gas turbine, or diesel engine) to produce electricity and use it for industrial processes, space conditioning, or as an energy source for another system component. This “cascading” of energy use is what distinguishes cogeneration systems from conventional separate electric and thermal energy systems (e.g., a powerplant and an industrial boiler), or from simple heat recovery strategies [1]. Most cogeneration systems can be described either as “topping” systems or “bottoming” systems, depending on whether the electrical or thermal energy is produced first. In a topping system—the most common cogeneration mode— electricity is produced first. The thermal energy that is exhausted is captured and used for such purposes as industrial processes, space heating and cooling, water heating, or even producing more electricity. Topping systems would be used in residential/commercial and most industrial cogeneration applications. In a bottoming system, high-temperature thermal energy is produced first for applications such as steel reheat furnaces, glass kilns, or aluminum remelt furnaces. Heat is extracted from the hot exhaust waste stream and transferred to a working fluid, generally through a waste heat recovery boiler. The fluid is vaporized and used to drive a turbine (Rankine cycle) to produce electrical energy. Bottoming cycles are used mostly in industries where high-temperature waste heat is available, and thus are limited to a few industrial processes. Further, they tend to have a higher capital cost than topping systems [1,2]. Topping systems can be further classified as combined cycle CHP plant, steam turbine CHP plant, internal combustion engine and gas turbine. When the emphasis is on the generation of electric power within the plant with high efficiency, the gas and steam cycles are combined into one arrangement. This arrangement uses a gas turbine to generate electricity from the fuel, in which, natural gas is added along with a stream of air, which combusts and expands through this turbine causing a generator to spin a magnet, producing electricity. From the process, there is waste heat that is recovered from the flue-gas through a heat recovery steam generator (HRSG) [2].Due to this arrangement, combined cycle plants are more efficient because they make use of the hot exhaust gases that would otherwise be dispelled from the system. These exhaust gases are used to boil water into steam—which can then spin another turbine and generate more electricity [3]. The thermal efficiency of the combined cycle can get up to 60% [4,5]. The advantages of a combined cycle are [3]: -Higher thermal efficiency -Lower capital investment -Faster starting and peaking times -Less thermal pollution (less energy discharge to cooling water per kWh) -Wide range of flexibility of power generation (thermal, mechanical, and electrical) In the current process, a cogeneration plant is presented. The CHP is composed of a gas turbine, a HRSG and a steam turbine.
B18: Process Diagram description
B19: The cogeneration plant is composed of a single shaft gas turbine, a heat recovery steam generator (HRSG), and a steam turbine [6,7]. The flow diagram presented above is described as follows. The cogeneration involves compression of air, the subsequent heating of this gas by burning a fuel without a change in pressure, followed by the expansion of the hot, pressurized gas. The compression process consumes power, while the expansion process extracts power from the gas. Some of the power from the expansion process is used to drive the compression process and the rest is used as useable power output [8]. The exhaust gases from the gas turbine are mixed and combusted with more natural gas, thus resulting in the increase in its temperature. The hot gases from the secondary combustion are carried out to the HRSG system and used to produce steam at different pressures[9]. The detailed description of the process is as follows: The single shaft gas turbine uses atmospheric air (15 °C, 1.02 bar) in excess to ensure complete combustion of the natural gas. For natural gas-fired burners, the stoichiometric air required is 9.4-11 ft.3 / 1.0 ft.3 of natural gas or approximately an air-to-gas ratio of approximately 24:1 (mol) [10]. In this case, the air flowrate is adjusted to maintain the combustion temperature below 1260 °C and reach an oxygen content of 13-15 mol% in the exhaust gas as required for the turbine and second burner [11,12]. A maximum turbine inlet temperature of over 1050 °C is preferred for thermal efficiency [13]. The air is then compressed in a multi-stage compressor with 15 stages and a compression ratio of 19.8:1, with equal compression ratio of 1.21 in each stage [7,14–16]. Isentropic efficiencies are taken to be constant, at 83% for the compressors and 90% for both the gas and steam turbines [17,18]. An intercooler is provided between each two stages of compression to cool air before it enters the next stage of compression[19]. The lower density of cool air makes it easier to compress than hot air. Ideally, the air should be as close to the ambient air temperature as possible. Typically, the intercooler is able to cool the compressed air within 20-30 degrees of the ambient air temperature[20]. The air is cooled to 40 °C in the intercooler [17,21] and it is used for the combustion of the natural gas. The natural gas (15 °C, 1.02 bar) composed mainly of CH4 and other components in lower concentrations (C2H6, C3H8, N2 and CO2) is defined and compressed to 20 bar to maintain well pressures and enable the burner to operate at the compressed air pressure [22]. Moreover, the compressed natural gas is heated to 300 °C before combustion. Increasing the inlet gas temperature from 240°C, abruptly increases the flame luminosity. This luminosity increase enhances the boiler efficiency and also causes significant reduction in flame temperature and NO emission. The results show that increasing the inlet gas temperature from 240°C to 300°C increases the flame luminous radiation by 60% and boiler efficiency by 20% [23]. In the burner, at these conditions, combustion temperatures of natural gas on air of 974 °C are reached. The hot exhaust gas is then sent to the turbine section, which consists of a high-efficiency 3-stage turbine operating at pressure ratios of around 1.5-5 [5, 14,24,25]. The industrial gas turbines have a lower pressure ratio and higher exhaust temperature to promote combined-cycle performance[26]. Such high exhaust discharge temperatures permit direct use of the exhaust[27]. For instance, maintaining the hot exhaust gas temperature is important to exchange heat in the countercurrent heat exchanger between the air and the exhaust gas [8]. By doing so, an increase in the air temperature for the first burner is achieved, and the gas turbine exhaust gases are conditioned to 500 °C, which is the final temperature of the turbine discharge exhaust gases and the required temperature for the second burner (supplementary firing system) [12]. More specifically, the exhaust gas of a gas turbine has an oxygen concentration of 13-15 wt%, temperature of 500- 600 °C, and in the exhaust supplementary firing system, only this exhaust gas is used as oxygen source for combustion. This supplementary firing burner helps a waste heat boiler increase output by reheating gas turbine exhaust with no additional air [12]. The reheated gas turbine exhaust gas is sent to a heat recovery steam generator (HRSG) section, in which it goes through a series of countercurrent heat exchangers to recover the heat from the turbine exhaust gasand convertswater into useful thermal energy in the form of steam. The current process consists of 3 heat recovery heat exchangers to produce high pressure-high temperature steam (HP), medium pressure (MP) steam and low pressure (LP)steam. HP and MP steam are also used to create additional power using steam turbines. The HRSG exhaust temperature is of around 160 °C, as reported for different HRSG systems [28]. Overall, the HRSG arrangement is composed of countercurrent heat exchangers to achieve the required steam temperatures and a series of pumps and turbines to adjust the pressure to produce the required HP, MP and LP steam [17,29,30], while producing electricity. Overall, the main products of the process are: electricity, HP, MP and LP steam. The main waste stream of the process is composed of exhaust flue gases like N2, O2, H2O and CO2 .
L36: LEGENDS
L37: FS- Feedstock/Raw material
L38: PS- Product
L39: WS-Waste
N41: LEGENDS
N42: FS- Feedstock/Raw material
N43: PS- Product
N44: WS-Waste
G65: Figure 1. Process Flow Diagram- CHP for electricity and steam production
B67: Mass Balances
B70: Raw materials | F70: Products | J70: Balance check
B71: Stream | C71: Composition (% mass) | D71: Flow kt/y | F71: Stream | G71: Composition (% mass) | H71: Flow kt/y | J71: Total inputs/outputs
B72: FS-AIR | C72: 23.3% O2, 76.7% N2 | D72: 3924.048 | F72: PS-LPS | G72: 100 % H2O | H72: 320 | J72: Raw materials (FS) | K72: =SUM(D72:D75) -> 4996.348
B73: FS-NG1 | C73: 70.5% CH4, 2.38% CO2, 21.78 N2, 4.88% N-C2A, 0.47% NC3-A | D73: 105 | F73: PS-MPS | G73: 100 % H2O | H73: 320 | J73: Products (PS) | K73: =SUM(H72:H74) -> 960
B74: FS-NG2 | C74: 70.5% CH4, 2.38% CO2, 21.78 N2, 4.88% N-C2A, 0.47% NC3-A | D74: 7.3 | F74: PS-HPS | G74: 100 % H2O | H74: 320 | J74: Waste Streams (WS) | K74: =H75 -> 4036.295
B75: FS-WATER | C75: 100 % H2O | D75: 960 | F75: WS-FLUEG | G75: 75.2% N2, 5.9% CO2, 14.3% O2, 4.7% H2O | H75: 4036.295
J76: Balance check | K76: =K72-K73-K74 -> 0.053
J77: Percent error (%) | K77: =(K76/K72)*100 -> 0.0010607748
B81: Energy Balances
K82: Utility process conditions
B83: Utility type | C83: Input - TJ/y | D83: Input - kt/y | E83: Output - TJ/y | F83: Output - kt/y | G83: Net - TJ/y | H83: Net - kt/y | I83: Remark | K83: Utility type | L83: Inlet temperature ( °C ) | M83: Outlet temperature ( °C ) | N83: Inlet pressure (bar) | O83: Outlet pressure (bar) | P83: Heat capacity/latent heat/lower heating value | Q83: Unit
B84: Low pressure steam | C84: 0 | D84: 0 | E84: -722.24 | F84: -320 | G84: -722.24 | H84: -320 | I84: Net Generation | K84: Very Low pressure steam | L84: - | M84: - | N84: - | O84: - | P84: - | Q84: -
B85: Mid pressure steam | C85: 0 | D85: 0 | E85: -604.8 | F85: -320 | G85: -604.8 | H85: -320 | I85: Net Generation | K85: Low pressure steam | L85: 155 | M85: 155 | N85: 5.5 | O85: 5.5 | P85: 2096.7716 | Q85: KJ/kg
B86: High pressure steam | C86: 0 | D86: 0 | E86: -524.8 | F86: -320 | G86: -524.8 | H86: -320 | I86: Net Generation | K86: Mid pressure steam | L86: 214 | M86: 214 | N86: 21 | O86: 21 | P86: 1879.6128 | Q86: KJ/kg
B87: Cooling water | C87: 1111.5201 | D87: 17759.2 | E87: 0 | F87: 0 | G87: 1111.5201 | H87: 17759.2 | K87: High pressure steam | L87: 265 | M87: 265 | N87: 51 | O87: 51 | P87: 1632.4494 | Q87: KJ/kg
B88: Fired Heat | C88: 708.04413 | D88: NA | E88: 0 | F88: NA | G88: 708.04413 | H88: NA | K88: Fired Heat | L88: 1000 | M88: 750 | N88: 2 | O88: 2 | P88: - | Q88: -
B89: Electricity | C89: 1407.1023 | D89: 48857.7 | E89: -2857.022 | F89: -99202,2 | G89: -1449.9197 | H89: -50344,5 | I89: Net Generation, kt/y values are kW | K89: Cooling water | L89: 25 | M89: 40 | N89: 1.02 | O89: 1.02 | P89: =62.74243314036/(M89-L89) -> 4.1828289 | Q89: KJ/kg.K
B90: *NA- Not Applicable | G90: =SUM(G84:G89) -> -1482.1955 | H90: =SUM(H84:H89) -> 16799.2
C92: Value | D92: Unit | E92: Remark
B93: TOTAL Energy requirements (kWh/y) from the other 5 plants in our system | C93: =SUM('Olefins Production Plant'!D134,'Aromatics Production Plant'!D153,'Biogas Plant'!C96,'Biogas Plant'!D96,'Methanol Production Plant'!D113,'DME Plant'!D106) -> 517970587 | D93: kWh/y | E93: Summed electricity inputs only (including the thermal and electric inputs for the biogas plant)
B94: Original production capacity (mW) | C94: 50 | D94: MW | E94: MW to kW = multiply by 1000
B95: Our assumption of operating hours per year | C95: 8765.82 | D95: h/y
...

Sheet Olefins Production Plant
B3: LOW OLEFINS PRODUCTION
B4: Process datasheet (Mass & Energy Balance)
B6: Production capacity | D6: Ethylene 876 kt/y, propylene 404 kt/y, acetylene 17 kt/y, butene 93 kt/y, butadiene 116 kt/y
B7: Operating hours per year | D7: 8000
B9: Overall Process Description
B10: The lower olefins are the primary feedstock for most plastics, polymers and chemicals and they comprise mainly ethylene, propylene, acetylene, butene and butadiene [1]. Steam cracking is currently the most commonly applied technology for the production of lower olefins. Steam cracking involves the high temperature pyrolysis (or cracking) of mainly saturated hydrocarbons in the presence of steam [1, 2]. The range of saturated hydrocarbons that can be used as feedstock for steam cracking is potentially wide. From the different feedstock alternatives, naphtha from crude oil refining is far the most important feedstock [1]. Hence, in this datasheet a model for steam cracking of naphtha feedstock is presented. During the steam cracking of naphtha, a wide range of lower hydrocarbons are produced mainly hydrogen, methane, ethylene, ethane, acetylene, propylene, propane, butene, butadiene, benzene, other non-aromatics and other aromatics [1, 3]. Thus, after steam cracking, the hydrocarbon mixture goes to the downstream purification section to separate the individual components. The downstream purification step consists of primary fractionation, gas clean-up, demethanizer, deethanize , acetylene extraction, C2-C2 splitter, depropanizer, C3-C3 splitter, debutanizer, butadiene extraction and aromatic extraction [1,2].
B18: Process Diagram description
B19: Naphtha feed at storage conditions is first pumped (O1-P1) and preheated (O1-E1) to 5 bar and 350 °C and is then mixed with superheated steam, at a steam to naphtha ratio of 0.5 (mass basis) [2]. The mixture is then heated to 500 °C and it enters the cracker furnace (O1-R1) operating at about 850 °C to ensure cracking of naphtha to lower olefins. The reaction being highly endothermic requires heat, which is supplied by burning off-gases produced within the olefin plant. The hot flue-gas from the furnace is used to preheat the feed and produce steam required for the process [2]. The hot olefin mixture from the furnace has an outlet pressure of 5 bar [3] and it is cooled to about 250 °C [1] (producing steam) before entering the quench tower. In the quench tower (O1-T1), the gas mixture is cooled down using recirculating quench liquid [1]. The mixture is then sent to a primary distillation tower (O1-T2) to remove heavy C9+ compounds like napthalene. The cooled olefin mixture is then compressed to about 30 bar using multistage compressor in order to facilitate the subsequent separation of different olefins [1]. During the compression, some of the BTX compounds get liquefied and are collected in a knock-out drum and sent to the benzene section for further processing [1]. As the cracked gas contains some CO and H2S [1], the gas has to be cleaned in order to prevent downstream processing problems like plugging and catalyst poisoning. Hence, a caustic scrubber (O1-T3) is typically used to remove unwanted gases. The scrubbing reactions are as follows: 2 NaOH + H2S → Na2S + 2 H2O CO + NaOH → HCO2Na (Sodium formate) During the scrubbing process some heavy components like benzene, toluene, p-xylene and styrene get removed from the gas and are recovered through phase separators, and then sent to the BTX section for further processing. The gas is then dried with a molecular sieve (O1-SP3) to remove any traces of water and it is sent to the downstream product separation section [2]. The downstream product separation section consists mainly of demethanizer, deethanizer, acetylene extraction, depropanizer, C3-C3 splitter, debutanizer, butadiene extraction and benzene extraction. In this section, the dried gas from the molecular sieve is first cooled in a cryogenic cooler (O1-E7) to -50 °C [2] and then fed to the demethanizer (O1-T4) operating at 30 bar [3]. In the demethanizer, methane and all the components lighter than methane are separated from the top. The gases from the demethanizer overhead are used for cryogenic cooling within the system and expanded to atmospheric conditions before being used as fuel gas in the system. The bottom stream enters the deethanizer column (O1-T5) operating at 25 bar [3] in which ethane and lighter components are removed from top. The deethanizer overhead contains mainly ethane, ethylene and acetylene and it is sent to the acetylene extraction section [2]. The bottom of the deethanizer is sent to the depropanizer (O1-T6) column operating at 20 bar [3]. In the depropanizer, propane and lighter components are removed from the top. The overhead contains mainly propylene and propane with methyl acetylene as impurity. This overhead C3 stream is sent to a hydrogenation reactor (O1-R2) to selectively hydrogenate methyl acetylene to propylene [3, 6]. The reaction is as follows: Methyl acetylene + H2 → Propylene From the reactor, the product stream goes to a C3-C3 splitter or propylene-propane splitter (O1-T7) working at 16 bar in which propylene product is obtained at the top and propane at the bottom [2]. The propylene product can be used to produce chemicals like propylene oxide and polypropylene. The bottom of the depropanizer is sent to the debutanizer column (O1-T8) operating at 15 bar. In the debutanizer, C4 components are removed from top and the bottom product is called pyrolysis gasoline or pygas. The overhead mixture from deethanizer column is sent to the acetylene extraction section in which acetylene is separated from ethylene using N-N-Dimethylformamide (DMF) [7]. In the acetylene extraction section, acetylene and ethane are selectively extracted at about 20 bar using DMF in O1-T9. This mixture is then sent to a stripper (O1-T10) operating at 1.02 bar with additional DMF fed to it. This column mainly removes dissolved ethane as top product, which can be used as fuel gas for furnace outside the system, and recovers acetylene at as bottom product. The bottom product is sent to the solvent regeneration column (O1-T11) to get acetylene product from the top and the regenerated solvent is recycled back [7]. The acetylene can be used for the production of vinyl esters and ethylene for a number of chemicals like ethylbenzene, ethylene dichloride and ethylene oxide [2]. The overhead of debutanizer mainly contains a mixture of butane, butene and butadiene. As butadiene forms an azeotrope with butane , extractive distillation with N-methylpyrrolidone (NMP) solvent is used for separation. A two stage extraction technique is used to separate the mixture. In the first column (O1-T15), the butene rich stream is separated from butadiene. The extract is sent to a rectification column (O1-T16) to recover the solvent. After rectification, in the third column or after washer (O1-T17) butadiene is separated from vinyl acetylene impurity [8, 9]. The vinyl acetate is recovered from solvent in O1-T18 and solvent is recycled back. The NMP solvent used contains 10% water to increase the selectivity of solvent and the solvent recovered are recycled back to the column with 10% water by adding make-up water [8]. The butadiene (BDI) product is sent to a decanter to remove excess water and pure BDI with 99 wt.% purity is obtained [8]. The butadiene produced can be used for Nylon 6,6 production and the butene can be used for isoprene production. The pygas recovered at the bottom of the debutanizer contains a mixture rich in BTX (Benzene, Toluene, Xylene) and it is blended with import pygas and heart-cut reformate. The resulting BTX mixture is first prefractionated in O1-T12 to remove as bottom product C7+ components which are known as pygas tail. The top product contains mainly C6 components and this mixture undergoes extractive distillation in O1-T13 with N-formylmorpholine (NFM) solvent. The non-aromatics stream is obtained as overhead raffinate and it is send to refinery for further usage. The benzene rich solvent is sent to a stripper column (O1-T14) operating at vacuum conditions to obtain pure benzene and the solvent is recycled back [13]. Overall, the main by-products of the process are: effluent water, flue-gas and off-gas. The main products of the process are: Ethylene, Propylene, Acetylene, Butene, Butadiene, Benzene and debenzenised pygas (pygas tail).
K36: LEGENDS
K37: FS- Feedstock/Raw material
K38: PS- Product
K39: WS-Waste
F72: Figure 1. Process Flow Diagram- Lower Olefins Production
B76: Mass Balances
B79: Raw materials | H79: Products | O79: Balance check
B80: Stream | C80: Composition (% mass) | D80: Flow kt/y | E80: Temperature ( °C ) | F80: Pressure (bar) | H80: Stream | I80: Composition (% mass) | J80: Flow kt/y | K80: Temperature ( °C ) | L80: Pressure (bar) | O80: Total inputs/outputs
B81: Naphtha | C81: ASTM D86 (IBP=26 C, FBP=183 C) | D81: 3000 | E81: 40 | F81: 1.02 | H81: Ethylene | I81: 99.99% Ethylene, 0.01% ethane | J81: 876.1176 | K81: -27 | L81: 20 | O81: Raw materials (FS) | P81: =SUM(D81:D92) -> 28767.139
B82: Steam | C82: 100% water | D82: 1500 | E82: 156 | F82: 5.5 | H82: Propylene | I82: 99.95% Propylene, 0.04% ethane, 0.01% propane | J82: 493.8954 | K82: 38 | L82: 16 | O82: Products (PS) | P82: =SUM(J81:J88) -> 2783.3348
B83: Combustion air | C83: 23% O2, 77% N2 | D83: 23311.12 | E83: 15 | F83: 1.02 | H83: Acetylene | I83: 99.62% acetylene, 0.02% propylene, 0.36% DMF | J83: 17.06651 | K83: 4 | L83: 1.02 | O83: Waste Streams (WS) | P83: =SUM(J94:J101) -> 25983.748
B84: NaOH | C84: 50% water, 50% NaOH | D84: 17.53785 | E84: 40 | F84: 1.02 | H84: Butene mixture | I84: 92% butene, 5% butane, 2.8% BDI, 0.2% water | J84: 92.55048 | K84: 30 | L84: 3
B85: Dilution water | C85: 100% water | D85: 146.5753 | E85: 15 | F85: 1.02 | H85: Butadiene | I85: 99.07% BDI, 0.71% butene, 0.11% water, 0.09% vinyl acetylene, 0.02% NMP | J85: 116.3208 | K85: 42 | L85: 8 | O85: Balance check | P85: =P81-P82-P83 -> 0.0558422
B86: NFM solvent | C86: 100% NFM | D86: 0.0313159 | E86: 15 | F86: 1.02 | H86: C9+ stream | I86: 0.02% H2O, 0.36% ethylene, 0.26% propylene, 2.2% Benzene, 0.11% BDI-13, 0.03% Acetylene, 0.08% Butene, 0.08% Methane, 0.05% ethane, 0.06% methyl acetylene, 12.06% p-xylene, 0.04% propylmercaptan, 60.11% naphthalene, 2.35% toluene, 3.63% ethyl benzene, 0.02% vinyl acetylene, 18.17% styrene, 0.37% cyclopentadiene | J86: 220.5914 | K86: 41 | L86: 2 | O86: Percent error (%) | P86: =(P85/P81)*100 -> 0.00019411802
B87: DMF solvent | C87: 100% DMF | D87: 0.081866 | E87: 15 | F87: 1.02 | H87: Benzene | I87: 99.995% benzene, 0.002% propylmercaptan, 0.001% methyhexane, 0.002% cyclohexane | J87: 672.5194 | K87: 95 | L87: 1.02
B88: Make-up water | C88: 100% water | D88: 1.498871 | E88: 15 | F88: 1.02 | H88: Non aromatic stream | I88: 7.52% benzene, 0.09% BDI-13, 0.06% butene, 6.7% propylene mercaptan, 0.02% vinyl acetylene, 56.45% cyclopentadiene, 27.76% hexane, 1.38% cyclohexane, 0.02% NFM | J88: 294.2732 | K88: 77 | L88: 2
B89: Make-up NMP | C89: 100% NMP | D89: 0.0262123 | E89: 15 | F89: 1.02
B90: H2 gas | C90: 99.87% H2, 0.13% N2 | D90: 1.143171 | E90: 40 | F90: 16
B91: Pygas import | C91: 70% benzene, 15% Cyclopentadiene, 10% Toluene, 5% hexane | D91: 372.2084 | E91: 15 | F91: 1.02
B92: HC Reformate import | C92: 50% benzene, 15% hexane, 10% 2-methyhexane, 10% 3-methyl heptane 5% o-xylene, 5% toluene, 3% ethylbenzene, 1% cyclohexane, 1% Cumene | D92: 416.9161 | E92: 15 | F92: 1.02 | H92: Waste streams
H93: Stream | I93: Concentration (wt %) | J93: Flow kt/y | K93: Temperature ( °C ) | L93: Pressure (bar)
H94: Flue gas | I94: 74.5% N2, 11.35% O2, 6.4% water, 7.74% CO2, 0.01% propyl mercaptan | J94: 23996.62 | K94: 200 | L94: 1.02
H95: Effluent | I95: 79.65% water, 0.62% ethylene, 1.23% propylene, 0.08% benzene, 0.01% acetylene, 0.87% butene, 0.07% butane, 0.05% methane, 0.13% ethane, 0.03% propane, 0.08% methyl acetylene, 4.1% propyl mercaptan, 0.02% toluene, 0.06% vinyl acetylene, 4.01% cyclopentadiene, 5.22% Na2S, 3.77% sodium formate | J95: 113.641 | K95: 40 | L95: 1.02
H96: Dirty water (WS-DW) | I96: 99.81% water, 0.02% ethylene, 0.01% propylene, 0.05% benzene, 0.1% propyl mercaptan, 0.01% cyclopentadiene | J96: 1470.525 | K96: 40 | L96: 2
H97: Water | I97: 100% water | J97: 91.84616 | K97: 6 | L97: 2
H98: Propane rich fuel gas | I98: 98.69% propane, 0.61% propylene, 0.39% BDI-13, 0.31% butene | J98: 10.58474 | K98: 46 | L98: 16
H99: Vinyl acetylene | I99: 94.35% vinyl acetylene, 0.35% water, 4.35% BDI-13, 0.53% butene, 0.42% Cyclopentadiene | J99: 4.957122 | K99: 38 | L99: 3
H100: Waste water | I100: 99.56% water, 0.09% BDI-13, 0.35% NMP | J100: 1.125432 | K100: 42 | L100: 2
H101: C7+ stream/Pygas tail | I101: 1.41% water, 0.3% benzene, 7.08% o-xylene, 2.62% p-xylene, 51.58% toluene, 6.01% ethylbenzene, 1.17% styrene, 0.04% Na2S, 0.03% HCOONA, 14.15% methylhexane, 14.15% methyl heptane, 0.04% cyclohexane, 1.42% cumene | J101: 294.449 | K101: 176 | L101: 5
B112: Energy Balances
B114: Utility type | C114: Input - TJ/y | D114: Input - kt/y | E114: Output - TJ/y | F114: Output - kt/y | G114: Net - TJ/y | H114: Net - kt/y | I114: Remark | K114: Utility process conditions
B115: Low pressure steam | C115: 7780.4913 | D115: 3711 | E115: -2659.2543 | F115: -1268 | G115: 5121.237 | H115: =D115+F115 -> 2443 | K115: Utility type | L115: Inlet temperature ( °C ) | M115: Outlet temperature ( °C ) | N115: Inlet pressure (bar) | O115: Outlet pressure (bar) | P115: Heat capacity/latent heat/lower heating value | Q115: Unit
...

Sheet Aromatics Production Plant
B3: AROMATICS PLANT
B4: Process datasheet (Mass & Energy Balance)
B6: Production capacity | D6: Benzene 892 kt/y, o-xylene production 186 kt/y, p-xylene 754 kt/y
B7: Operating hours per year | D7: 8000 h/y
B9: Overall Process Description
B10: Aromatics are a category of compounds based on benzene rings at their cores. Aromatics plants produce chemicals like benzene, toluene, xylenes, ethylbenzene, cyclohexane, styrene, nitrobenzene (with some exceptions, like furans). The primary source of aromatics is the crude from the catalytic reforming process, also called reformate, which is used after the lighter (C4-C5) compounds have been removed. Another source of aromatics is the naphtha obtained as an outcome of the steam cracking process, called pyrolysis gas or pygas. The pygas obtained from crackers has a higher content of sulphur compounds compared to the reformate [2]. Thus, a desulphurization step is required as a pre-treatment to avoid catalyst poisoning. Moreover, a hydrofining process is required to hydrogenate (di)olefins and unsaturated aromatics from the pygas and reformate [6]. Overall, the pre-treatment section comprises pre-distillation to remove heavy compounds (C9+), and hydrogenation and stabilizing sections to remove sulphur compounds [6]. After the pre-treatment, the gas mix goes to a sulfolane extraction unit (SEU) to separate the aromatics from the non-aromatics using extractive distillation, since a normal distillation will not be efficient to separate these close boiling compounds. The distillate product contains light component and non-aromatics (like methylheptane) and some sulfolane and thus, it is sent to water stripping to recover the remaining solvent and non-aromatics. On the other hand, the bottom product from the extraction column is sent to a solvent regeneration column, where pure sulfolane is recovered and used back in the extraction process. The concentrated BTX (Benzene, toluene and xylenes) is now sent to clay pre-treatment to remove the remaining olefins and light compounds, and is further sent to the fractionation section [6]. In the fractionation section, each individual aromatic component is subsequently separated in a distillation column- starting with benzene, followed by toluene and finally in the third column the xylenes are recovered. The further the toluene disproportionation to produce benzene and xylenes (selectively para-xylene) is addressed, as well as the isomerization of meta-xylene to produce ortho- and para-xylenes. Para- and Ortho- xylenes are the end products of the Xylene separation unit.
B18: Process Diagram description
B19: The aromatics plant consists of several sections including pre-distillation, hydrogenation, desulfurization, BTX extraction using sulfonale as solvent, clay treatment, BTX fractionation into benzene, toluene and xylenes. These sections are followed by toluene disproportionation into benzene and xylenes and finally the xylenes cryztallization, isomerization and separation section. All of these processes take place over a wide range of temperature and pressures. For instance, it goes from pre-distillation in vacuum (0.2-1.02 bar) to toluene disproportionation at high pressures (30 bar), from xylenes isomerization at high temperatures (400˚C) to crystallization using refrigerants (-15˚C). Pre-distillation section: The reformate and pygas enter the process at 25˚C and 1,02 bar and are mixed with the C7+ fraction to be pre-treated together (feed conditioning process). For this, the mixed feed is first heated to 116˚ C and then sent to an atmospheric pre-distillation step to remove the C9+ components like 1,2,4-Trimethylbenzene and dicyclopentadiene. A second distillation column operating under vacuum (0 .2 bar) is used to avoid the polymerization reactions and improve the separation of the C9+ components from the aromatic mix [6]. Hydrotreating section: The mixture free of C9+ components is subsequently hydrogenated, in which the diolefins and unsaturated aromatics (isoprene, styrene, butadiene, etc.) are treated with hydrogen to create saturated hydrocarbons. A trickle bed reactor with nickel or palladium-based catalysts working at 400˚ C and 26 bar is used for the hydrogenation process [6], [8]. Part of the reactor effluent is recycled back to the hydrotreating step to keep the reactor temperature down. The recycled stream is cooled down to 120 ˚C and mixed with the main feed and fresh hydrogen before entering the hydrotreating reactor. The reactor system is normally designed for a ratio of recycled to fresh feed of between 2:1 and 3:1 [6]. The remaining part of the effluent, is sent to the second hydrogenation step. The feed to the second reactor is mixed with recycled hydrogen and raised to the required feed temperature of 275 ˚C. In this step, the sulphur compounds are reduced mainly to H2S over cobalt/molybdenum catalyst [6]. This unit also reduces the olefins to paraffins over nickel/molybdenum catalyst. The reactor effluent is cooled down through heat transfer with the reactor’s inlet flow, and is sent to a hot vapour-liquid separator drum. The vapour from this drum is further cooled down to -36˚ C and sent to a cold vapour-liquid separator drum from which the gas consisting of hydrogen and lighter hydrocarbons is sent to the compressor and recycled and mixed with the 2nd reactor feed [6], [8], [9]. A recycle gas purge is maintained to avoid accumulation of light hydrocarbons in the hydrogen-rich stream. From the vapour-liquid separators, the liquid streams are collected and distilled at ambient conditions to remove H2S, which is recovered as distillate and vented out as raffinate [6]. The bottom stream is sent to extraction section for non-aromatics separation. Sulfonale extraction section: Since the aromatics and non-aromatics have close boiling points, it is not possible to separate them effectively by asimple distillation process. Instead, a 99% sulfolane solvent is used to extract the aromatics and separate the non-aromatics in a single column [10]. The sulfolane extraction unit operates at 2 bar and between 125-180˚C. The distillate from the extraction column goes to a raffinate wash column, where the excess sulfolane solvent is washed down with water and the non-aromatic distillate is vented from the top as a gasoline product [1]. The sulfolane-water stream from the wash column is sent to a decanter, where the remaining non-aromatics are removed from the water and sulfonale[11]. On the other hand, the bottom stream from the sulfonale extraction column is sent to a solvent recovery column operating under vacuum (0,4 bar) to recover the sulfolane solvent and concentrate the aromatics product stream. The solvent-rich stream is mixed with the solvent from the decanter and then pumped back to the extraction column[11]. The concentrated BTX obtained as a distillate from this unit, after been hydrotreated and distilled to remove the dienes and at least 70% of the olefins, it is clay treated to remove the remaining olefins. The clay treating is carried out at a temperature of 100 °C and at a pressure of 7.9 bar [12]. BTX Separation: This distillate, rich in aromatics, is then fractionated in a series of distillation columns to recover Benzene (Purity 99.99%), Toluene and Xylenes at vacuum conditions (0.5-0.8 bar)[6]. Toluene Disproportionation: The toluene obtained from the second column is mixed with hydrogen. The hydrogen-to-toluene ratio is about 1 to 1.5. The mixed stream is heated against reactor effluent and through a process furnace. The heated vapor stream flows to the reactor, which produces the benzene and xylenes (majorly p-xylene, with >96% selectivity) in a disproportionation reaction operated at 400˚C and 30 bar [1], [13]–[15]. The toluene disproportionation reactions are mildly exothermic and thus, the reactor effluent is cooled and sent to a separator, where the hydrogen-rich vapor phase is separated from the liquid stream. A small portion of the vapor phase is purged to control recycle hydrogen purity. The recycled hydrogen is then compressed, mixed with makeup hydrogen and returned to the reactor [14], [15]. About 50% Toluene is disproportionated to benzene and (mixed) xylenes [6]. The reaction mixture is then recycled back to the beginning of the fractionation to separate out benzene and xylenes. Xylenes Loop: The xylenes mixture from the bottom of the last column of the BTX fractionation section is pumped to the xylenes separation section. In this section, ortho-xylene is recovered in a first column as a bottoms product (mole purity of 99.5%), leaving the meta and para xylenes (along with ethylbenzene) in the distillate[16]. This distillate, is then cooled to 20 ˚C and sent to a crystallizer unit operating at -15 ˚C to separate out para-xylene from the stream [6], [17]. Para-xylene has the highest melting point among the xylenes (13,3˚C, compared to -25,2˚C for o-xylene and -47,9 ˚C for m-xylene) and can be removed from the mixture by crystallization, which has certain advantages over zeolites adsorption process [6][18][19]. A product mass purity of about 99,5% para-xylene is obtained from this separation [18]. The remaining raffinate stream is further sent to a Liquid Isoformer Unit (LIU) in gas phase under hydrogen pressure, where the meta-xylene is converted to ortho- and para-xylenes at >400˚C [1]. In essence, an equilibrium between the compositions of xylenes from before the crystallization unit is obtained in the isoformer unit [6]. As a side reaction of the isoformer, ethylbenzene is converted to benzene and ethane in a hydrogen-rich environment [1]. At least 50% conversion of ethyl benzene in the feed which is isomerized [20]. After the isomerization, the reactor effluent is passed to a separator where the liquid phase comprising benzene and xylenes is separated from the gaseous phase comprising hydrogen, ethane, and some benzene. The gaseous phase withdrawn from separator is cooled, typically about 10 ˚C and 14 bar, and introduced into a series of absorption towers with intermediate cooling to separate the hydrogen [22] and recycle it back to the isoformer, while the benzene and remaining ethane are removed from the rich-xylenes stream by distillation [1]. The benzene is recovered as distillate and is recycled back to the SEU for subsequent benzene recovery [23]. The bottoms stream from the distillation is sent to a deheptanizer to remove the C7+ components from the mixture, and the xylenes-rich stream recovered from this column is recycled back to the xylenes separation section to recover ortho- and para- xylene concentrates[6].
O58: LEGENDS
O59: FS- Feedstock/Raw material
O60: PS- Product
O61: WS-Waste
G97: Figure 1. Process Flow Diagram- Aromatics Production
B99: Mass Balances
B102: Raw materials | I102: Products | P102: Balance check
B103: Stream | C103: Stream Name | D103: Composition (% mass) | E103: Flow kt/y | F103: Temp (˚C) | G103: Pressure (bar) | I103: Stream | J103: Stream Name | K103: Composition (% mass) | L103: Flow kt/y | M103: Temp (˚C) | N103: Pressure (bar) | P103: Total inputs/outputs
B104: Reformate | C104: FS-REFM | D104: Reported below | E104: 1866.2497 | F104: 25 | G104: 1.02 | I104: Benzene product | J104: PS-BENZ | K104: Benzene (99.99%) | L104: 891.73724 | M104: 40 | N104: 1.02 | P104: Raw materials (FS) | Q104: =SUM(E104:E112) -> 4753.8973
B105: Pygas | C105: FS-PYGAS | D105: Reported below | E105: 2220.7035 | F105: 25 | G105: 1.02 | I105: O-xylene product | J105: PS-OXYL | K105: o-xylene (99.54%), m-xylene (0.02%), p-xylene (0.41%), cumene (0.02%) | L105: 185.68273 | M105: 40.1 | N105: 1.02 | P105: Products (PS) | Q105: =SUM(L104:L106) -> 1831.5265
B106: C7+ stream/Pygas tail | C106: FS-C7+ | D106: Benzene (0.2%), Toluene (40.3%), o-Xylene (5.5%), m-Xylene (8.5%), Water (2%), Naphth (3.3%), Styrene (10.6%), EB (6.6%), 2-MEHX (10.9%), 3-MEHP (10.9%), Cumene (1.2%) | E106: 381.5588 | F106: 180.3 | G106: 5 | I106: P-xylene product | J106: PS-PXYL | K106: o-xylene (0.11%), p-xylene (99.78%), EB (0.11%) | L106: 754.10652 | M106: 22.337442 | N106: 1.02 | P106: Waste Streams (WS) | Q106: =SUM(L112:L128) -> 2922.6508
B107: H2 for hydrofining | C107: FS-H2 | D107: H2 (99.87%), N2 (0.13%) | E107: 23.632905 | F107: 30 | G107: 16
B108: H2 for desulphurization | C108: FS-H2IN | D108: H2 (99.87%), N2 (0.13%) | E108: 0.4843956 | F108: 30 | G108: 16 | P108: Balance check | Q108: =Q104-Q105-Q106 -> -0.27991442
B109: H2 for Toluene disproportionation | C109: FS-H2TOL | D109: H2 (99.87%), N2 (0.13%) | E109: 0.17595939 | F109: 30 | G109: 16 | P109: Percent error (%) | Q109: =(Q108/Q104)*100 -> -0.0058881041
B110: H2 for Isoformer unit | C110: FS-HYDRO | D110: H2 (99.87%), N2 (0.13%) | E110: 4.9174463 | F110: 30 | G110: 16 | I110: Waste streams
B111: Water for wash | C111: FS-WAT | D111: Water (100%) | E111: 129.71002 | F111: 15 | G111: 1.02 | I111: Stream | J111: Stream Name | K111: Composition (mass) | L111: Flowrate - ktonne/y | M111: Temp (˚C) | N111: Pressure (bar)
B112: Solvent | C112: FS-SULFO | D112: Sulfonale (99%), Water (1%) | E112: 126.46465 | F112: 40 | G112: 1.02 | I112: Remaining heavy components C9+ | J112: WS-2C9+ | K112: o-xylene (8.87%), m-xylene (0.93%), p-xylene (1.03%), SL (0.73%), NAPH (0.01%), DCYPD (17.81%), EB (0.15%), TMB (61.88%), Cumene (8.58%) | L112: 45.100113 | M112: 40 | N112: 1.02
I113: Heavy components C9+ | J113: WS-C9+ | K113: o-xylene (0.10%), NAPH (23.15%), DCYPD (12.18%), Styrene (0.12%), TMB (64.00%), BZAC (0.34%), Cumene (0.11%) | L113: 605.35449 | M113: 40 | N113: 1.02
I114: Ethane by-product | J114: WS-ETHAN | K114: H2 (0.07%), N2 (0.01%), N-C2A (99.92%) | L114: 47.390966 | M114: -53.888889 | N114: 14
I115: Aromatics removed from Hydrogen | J115: WS-HEAVY | K115: BZ (42.83%), TOL (0.63), o-xylene (2.24%), m-xylene (37.58%), p-xylene (15.21%), EB (1.50%) | L115: 20.197886 | M115: 40 | N115: 1.02
